2021-01-04 13:03:28,829 ERROR: Exception on /questionlist/0 [POST] [in D:\Documenten\Projects\DataEnWatNu\env\lib\site-packages\flask\app.py:1891] - [from 127.0.0.1 to http://127.0.0.1:5000/questionlist/0]
Traceback (most recent call last):
  File "D:\Documenten\Projects\DataEnWatNu\env\lib\site-packages\sqlalchemy\engine\base.py", line 1276, in _execute_context
    self.dialect.do_execute(
  File "D:\Documenten\Projects\DataEnWatNu\env\lib\site-packages\sqlalchemy\engine\default.py", line 593, in do_execute
    cursor.execute(statement, parameters)
psycopg2.errors.ForeignKeyViolation: insert or update on table "Answer" violates foreign key constraint "Answer_case_fkey"
DETAIL:  Key (case)=(12) is not present in table "Case".


The above exception was the direct cause of the following exception:

Traceback (most recent call last):
  File "D:\Documenten\Projects\DataEnWatNu\env\lib\site-packages\flask\app.py", line 2447, in wsgi_app
    response = self.full_dispatch_request()
  File "D:\Documenten\Projects\DataEnWatNu\env\lib\site-packages\flask\app.py", line 1952, in full_dispatch_request
    rv = self.handle_user_exception(e)
  File "D:\Documenten\Projects\DataEnWatNu\env\lib\site-packages\flask\app.py", line 1821, in handle_user_exception
    reraise(exc_type, exc_value, tb)
  File "D:\Documenten\Projects\DataEnWatNu\env\lib\site-packages\flask\_compat.py", line 39, in reraise
    raise value
  File "D:\Documenten\Projects\DataEnWatNu\env\lib\site-packages\flask\app.py", line 1950, in full_dispatch_request
    rv = self.dispatch_request()
  File "D:\Documenten\Projects\DataEnWatNu\env\lib\site-packages\flask\app.py", line 1936, in dispatch_request
    return self.view_functions[rule.endpoint](**req.view_args)
  File "D:\Documenten\Projects\DataEnWatNu\src\blueprints\questions\routes.py", line 19, in question
    Answer.create(answer=answer, answeredquestion=question.id, case=session_id)
  File "D:\Documenten\Projects\DataEnWatNu\src\database.py", line 42, in create
    instance = cls(**kwargs)
  File "<string>", line 4, in __init__
  File "D:\Documenten\Projects\DataEnWatNu\env\lib\site-packages\sqlalchemy\orm\state.py", line 433, in _initialize_instance
    manager.dispatch.init_failure(self, args, kwargs)
  File "D:\Documenten\Projects\DataEnWatNu\env\lib\site-packages\sqlalchemy\util\langhelpers.py", line 68, in __exit__
    compat.raise_(
  File "D:\Documenten\Projects\DataEnWatNu\env\lib\site-packages\sqlalchemy\util\compat.py", line 182, in raise_
    raise exception
  File "D:\Documenten\Projects\DataEnWatNu\env\lib\site-packages\sqlalchemy\orm\state.py", line 430, in _initialize_instance
    return manager.original_init(*mixed[1:], **kwargs)
  File "D:\Documenten\Projects\DataEnWatNu\src\database.py", line 69, in __init__
    self.update(**kwargs)
  File "D:\Documenten\Projects\DataEnWatNu\src\database.py", line 48, in update
    return self.save()
  File "D:\Documenten\Projects\DataEnWatNu\src\database.py", line 54, in save
    db.session.commit()
  File "D:\Documenten\Projects\DataEnWatNu\env\lib\site-packages\sqlalchemy\orm\scoping.py", line 163, in do
    return getattr(self.registry(), name)(*args, **kwargs)
  File "D:\Documenten\Projects\DataEnWatNu\env\lib\site-packages\sqlalchemy\orm\session.py", line 1042, in commit
    self.transaction.commit()
  File "D:\Documenten\Projects\DataEnWatNu\env\lib\site-packages\sqlalchemy\orm\session.py", line 504, in commit
    self._prepare_impl()
  File "D:\Documenten\Projects\DataEnWatNu\env\lib\site-packages\sqlalchemy\orm\session.py", line 483, in _prepare_impl
    self.session.flush()
  File "D:\Documenten\Projects\DataEnWatNu\env\lib\site-packages\sqlalchemy\orm\session.py", line 2536, in flush
    self._flush(objects)
  File "D:\Documenten\Projects\DataEnWatNu\env\lib\site-packages\sqlalchemy\orm\session.py", line 2678, in _flush
    transaction.rollback(_capture_exception=True)
  File "D:\Documenten\Projects\DataEnWatNu\env\lib\site-packages\sqlalchemy\util\langhelpers.py", line 68, in __exit__
    compat.raise_(
  File "D:\Documenten\Projects\DataEnWatNu\env\lib\site-packages\sqlalchemy\util\compat.py", line 182, in raise_
    raise exception
  File "D:\Documenten\Projects\DataEnWatNu\env\lib\site-packages\sqlalchemy\orm\session.py", line 2638, in _flush
    flush_context.execute()
  File "D:\Documenten\Projects\DataEnWatNu\env\lib\site-packages\sqlalchemy\orm\unitofwork.py", line 422, in execute
    rec.execute(self)
  File "D:\Documenten\Projects\DataEnWatNu\env\lib\site-packages\sqlalchemy\orm\unitofwork.py", line 586, in execute
    persistence.save_obj(
  File "D:\Documenten\Projects\DataEnWatNu\env\lib\site-packages\sqlalchemy\orm\persistence.py", line 239, in save_obj
    _emit_insert_statements(
  File "D:\Documenten\Projects\DataEnWatNu\env\lib\site-packages\sqlalchemy\orm\persistence.py", line 1083, in _emit_insert_statements
    c = cached_connections[connection].execute(statement, multiparams)
  File "D:\Documenten\Projects\DataEnWatNu\env\lib\site-packages\sqlalchemy\engine\base.py", line 1011, in execute
    return meth(self, multiparams, params)
  File "D:\Documenten\Projects\DataEnWatNu\env\lib\site-packages\sqlalchemy\sql\elements.py", line 298, in _execute_on_connection
    return connection._execute_clauseelement(self, multiparams, params)
  File "D:\Documenten\Projects\DataEnWatNu\env\lib\site-packages\sqlalchemy\engine\base.py", line 1124, in _execute_clauseelement
    ret = self._execute_context(
  File "D:\Documenten\Projects\DataEnWatNu\env\lib\site-packages\sqlalchemy\engine\base.py", line 1316, in _execute_context
    self._handle_dbapi_exception(
  File "D:\Documenten\Projects\DataEnWatNu\env\lib\site-packages\sqlalchemy\engine\base.py", line 1510, in _handle_dbapi_exception
    util.raise_(
  File "D:\Documenten\Projects\DataEnWatNu\env\lib\site-packages\sqlalchemy\util\compat.py", line 182, in raise_
    raise exception
  File "D:\Documenten\Projects\DataEnWatNu\env\lib\site-packages\sqlalchemy\engine\base.py", line 1276, in _execute_context
    self.dialect.do_execute(
  File "D:\Documenten\Projects\DataEnWatNu\env\lib\site-packages\sqlalchemy\engine\default.py", line 593, in do_execute
    cursor.execute(statement, parameters)
sqlalchemy.exc.IntegrityError: (psycopg2.errors.ForeignKeyViolation) insert or update on table "Answer" violates foreign key constraint "Answer_case_fkey"
DETAIL:  Key (case)=(12) is not present in table "Case".

[SQL: INSERT INTO "Answer" (answeredquestion, answer, "case") VALUES (%(answeredquestion)s, %(answer)s, %(case)s)]
[parameters: {'answeredquestion': 1, 'answer': '123', 'case': 12}]
(Background on this error at: http://sqlalche.me/e/13/gkpj)
2021-01-04 13:11:21,522 ERROR: Exception on /questionlist/3 [GET] [in D:\Documenten\Projects\DataEnWatNu\env\lib\site-packages\flask\app.py:1891] - [from 127.0.0.1 to http://127.0.0.1:5000/questionlist/3]
Traceback (most recent call last):
  File "D:\Documenten\Projects\DataEnWatNu\env\lib\site-packages\flask\app.py", line 2447, in wsgi_app
    response = self.full_dispatch_request()
  File "D:\Documenten\Projects\DataEnWatNu\env\lib\site-packages\flask\app.py", line 1952, in full_dispatch_request
    rv = self.handle_user_exception(e)
  File "D:\Documenten\Projects\DataEnWatNu\env\lib\site-packages\flask\app.py", line 1821, in handle_user_exception
    reraise(exc_type, exc_value, tb)
  File "D:\Documenten\Projects\DataEnWatNu\env\lib\site-packages\flask\_compat.py", line 39, in reraise
    raise value
  File "D:\Documenten\Projects\DataEnWatNu\env\lib\site-packages\flask\app.py", line 1950, in full_dispatch_request
    rv = self.dispatch_request()
  File "D:\Documenten\Projects\DataEnWatNu\env\lib\site-packages\flask\app.py", line 1936, in dispatch_request
    return self.view_functions[rule.endpoint](**req.view_args)
  File "D:\Documenten\Projects\DataEnWatNu\src\blueprints\questions\routes.py", line 12, in question
    question = Question.get_by_id(question_order[question_id])
IndexError: list index out of range
2021-01-04 13:11:21,522 ERROR: Exception on /questionlist/3 [GET] [in D:\Documenten\Projects\DataEnWatNu\env\lib\site-packages\flask\app.py:1891] - [from 127.0.0.1 to http://127.0.0.1:5000/questionlist/3]
Traceback (most recent call last):
  File "D:\Documenten\Projects\DataEnWatNu\env\lib\site-packages\flask\app.py", line 2447, in wsgi_app
    response = self.full_dispatch_request()
  File "D:\Documenten\Projects\DataEnWatNu\env\lib\site-packages\flask\app.py", line 1952, in full_dispatch_request
    rv = self.handle_user_exception(e)
  File "D:\Documenten\Projects\DataEnWatNu\env\lib\site-packages\flask\app.py", line 1821, in handle_user_exception
    reraise(exc_type, exc_value, tb)
  File "D:\Documenten\Projects\DataEnWatNu\env\lib\site-packages\flask\_compat.py", line 39, in reraise
    raise value
  File "D:\Documenten\Projects\DataEnWatNu\env\lib\site-packages\flask\app.py", line 1950, in full_dispatch_request
    rv = self.dispatch_request()
  File "D:\Documenten\Projects\DataEnWatNu\env\lib\site-packages\flask\app.py", line 1936, in dispatch_request
    return self.view_functions[rule.endpoint](**req.view_args)
  File "D:\Documenten\Projects\DataEnWatNu\src\blueprints\questions\routes.py", line 12, in question
    question = Question.get_by_id(question_order[question_id])
IndexError: list index out of range
